<mujoco model="swimmer">
  <compiler inertiafromgeom="true" angle="degree" coordinate="local" />

  <custom>
    <numeric name="frame_skip" data="200" />
  </custom>
  <option timestep="0.001" density="4000" viscosity="0.1" collision="predefined" integrator="Euler" iterations="1000">
    <flag warmstart="disable" />
  </option>
  
  <default>
    <geom contype='1' conaffinity='1' condim='1' rgba='0.8 0.6 .4 1' material="geom" />

  </default>
  <asset>
    <texture type="skybox" builtin="gradient" width="100" height="100" rgb1="1 1 1" rgb2="0 0 0" />
    <texture name="texgeom" type="cube" builtin="flat" mark="cross" width="127" height="1278" rgb1="0.8 0.6 0.4" rgb2="0.8 0.6 0.4" markrgb="1 1 1" random="0.01" />
    <texture name="texplane" type="2d" builtin="checker" rgb1="0 0 0" rgb2="0.8 0.8 0.8" width="100" height="100" />
    <material name='MatPlane' texture="texplane" shininess="1" texrepeat="30 30" specular="1"  reflectance="0.5" />
    <material name='geom' texture="texgeom" texuniform="true" />
  </asset>
  <worldbody>
    <light directional="true" cutoff="100" exponent="1" diffuse="1 1 1" specular=".1 .1 .1" pos="0 0 1.3" dir="-0 0 -1.3" />
    <geom name='floor' material="MatPlane" pos='0 0 -0.1' size='40 40 0.1' type='plane' conaffinity='3' contype='3' rgba='0.8 0.9 0.8 1' condim='3' />
    <geom name='left_wall' pos='-2.5 0 0' size='0.1 2.5 0.5' type='box' conaffinity='1' rgba='1 0 0 1' contype='3'/>
    <geom name='right_wall' pos='2.5 0 0' size='0.1 2.5 0.5' type='box' conaffinity='1' rgba='1 0 0 1' contype='3'/>
    <geom name='front_wall' pos='0 2.5 0' size='2.5 0.1 0.5' type='box' conaffinity='1' rgba='1 0 0 1' contype='3'/>
    <geom name='back_wall' pos='0 -2.5 0' size='2.5 0.1 0.5' type='box' conaffinity='1' rgba='1 0 0 1' contype='3'/>

    <body name="torso" pos="0 0 0">
      <geom name="torso" type="capsule" fromto="1.5 0 0 0.5 0 0" size="0.1" density="1000" conaffinity='1' contype='3'/>
      <joint pos="0 0 0" type="slide" name="slider1" axis="1 0 0" />
      <joint pos="0 0 0" type="slide" name="slider2" axis="0 1 0" />
      <joint name="rot" type="hinge" pos="0 0 0" axis="0 0 1" />
      <body name="mid" pos="0.5 0 0">
        <geom name="mid" type="capsule" fromto="0 0 0 -1 0 0" size="0.1" density="1000" conaffinity='1' contype='3'/>
        <joint name="rot2" type="hinge" pos="0 0 0" axis="0 0 1" range="-100 100" limited="true" />
        <body name="back" pos="-1 0 0">
          <geom name="back" type="capsule" fromto="0 0 0 -1 0 0" size="0.1" density="1000" conaffinity='1' contype='3'/>
          <joint name="rot3" type="hinge" pos="0 0 0" axis="0 0 1" range="-100 100" limited="true" />
        </body>
      </body>
    </body>>
  </worldbody>
  <actuator>
    <velocity joint="rot2" ctrllimited="true" ctrlrange="-300 300" />
    <velocity joint="rot3" ctrllimited="true" ctrlrange="-300 300" />
  </actuator>
  <contact>
    <pair geom1='torso' geom2='right_wall'/>
    <pair geom1='torso' geom2='left_wall'/>
    <pair geom1='torso' geom2='front_wall'/>
    <pair geom1='torso' geom2='back_wall'/>

    <pair geom1='mid' geom2='right_wall'/>
    <pair geom1='mid' geom2='left_wall'/>
    <pair geom1='mid' geom2='front_wall'/>
    <pair geom1='mid' geom2='back_wall'/>

    <pair geom1='back' geom2='right_wall'/>
    <pair geom1='back' geom2='left_wall'/>
    <pair geom1='back' geom2='front_wall'/>
    <pair geom1='back' geom2='back_wall'/>
  </contact>
</mujoco>
